[32m2024-12-13 00:35:08 +0100[0m - dagster - [34mDEBUG[0m - today_weather_trends_pipeline - 73b59ea9-083a-4e90-b391-250be93b15ba - 37863 - LOGS_CAPTURED - Started capturing logs in process (pid: 37863).
[32m2024-12-13 00:35:08 +0100[0m - dagster - [34mDEBUG[0m - today_weather_trends_pipeline - 73b59ea9-083a-4e90-b391-250be93b15ba - 37863 - store_weather_data - STEP_START - Started execution of step "store_weather_data".
[32m2024-12-13 00:35:08 +0100[0m - dagster - [34mDEBUG[0m - today_weather_trends_pipeline - 73b59ea9-083a-4e90-b391-250be93b15ba - store_weather_data - Loading file from: /Users/erendestan/Documents/DDBL/Projects/InnolabsRainmaker/tmphhdrxrys/storage/73b59ea9-083a-4e90-b391-250be93b15ba/fetch_weather_data/result using PickledObjectFilesystemIOManager...
[32m2024-12-13 00:35:08 +0100[0m - dagster - [34mDEBUG[0m - today_weather_trends_pipeline - 73b59ea9-083a-4e90-b391-250be93b15ba - 37863 - store_weather_data - LOADED_INPUT - Loaded input "weather_data" using input manager "io_manager", from output "result" of step "fetch_weather_data"
[32m2024-12-13 00:35:08 +0100[0m - dagster - [34mDEBUG[0m - today_weather_trends_pipeline - 73b59ea9-083a-4e90-b391-250be93b15ba - 37863 - store_weather_data - STEP_INPUT - Got input "weather_data" of type "Any". (Type check passed).
ERROR:root:Error storing weather data: 'APIResponse[TypeVar]' object has no attribute 'error'
[32m2024-12-13 00:35:08 +0100[0m - dagster - [34mERROR[0m - [31mtoday_weather_trends_pipeline - 73b59ea9-083a-4e90-b391-250be93b15ba - 37863 - store_weather_data - STEP_FAILURE - Execution of step "store_weather_data" failed.

dagster._core.errors.DagsterExecutionStepExecutionError: Error occurred while executing op "store_weather_data"::

AttributeError: 'APIResponse[TypeVar]' object has no attribute 'error'

Stack Trace:
  File "/opt/anaconda3/envs/weatherapi_report/lib/python3.13/site-packages/dagster/_core/execution/plan/utils.py", line 54, in op_execution_error_boundary
    yield
  File "/opt/anaconda3/envs/weatherapi_report/lib/python3.13/site-packages/dagster/_utils/__init__.py", line 467, in iterate_with_context
    next_output = next(iterator)
  File "/opt/anaconda3/envs/weatherapi_report/lib/python3.13/site-packages/dagster/_core/execution/plan/compute_generator.py", line 131, in _coerce_op_compute_fn_to_iterator
    result = invoke_compute_fn(
        fn, context, kwargs, context_arg_provided, config_arg_class, resource_arg_mapping
    )
  File "/opt/anaconda3/envs/weatherapi_report/lib/python3.13/site-packages/dagster/_core/execution/plan/compute_generator.py", line 125, in invoke_compute_fn
    return fn(context, **args_to_pass) if context_arg_provided else fn(**args_to_pass)
                                                                    ~~^^^^^^^^^^^^^^^^
  File "/Users/erendestan/Documents/DDBL/Projects/InnolabsRainmaker/database_data_pipeline.py", line 72, in store_weather_data
    if response.error:
       ^^^^^^^^^^^^^^
  File "/opt/anaconda3/envs/weatherapi_report/lib/python3.13/site-packages/pydantic/main.py", line 892, in __getattr__
    raise AttributeError(f'{type(self).__name__!r} object has no attribute {item!r}')
[0m
